Workbook

Sheet ダッシュボード
B1: YAGATE LIVE ダッシュボード
B2: 「公演データ」シートに実績を入力すると自動更新されます。
B4: ■ 全期間サマリー
B5: 公演数 | C5: 累計販売枚数 | D5: 累計売上 | E5: 累計粗利
B6: =COUNTA(公演データ!$A$3:$A$40) -> 38 | C6: =SUM(公演データ!$J$3:$J$40) -> 1071 | D6: =SUM(公演データ!$R$3:$R$40) -> 1603080 | E6: =SUM(公演データ!$X$3:$X$40) -> -533120
B8: 平均粗利率 | C8: 平均販売枚数 | D8: 平均客単価 | E8: 平均消化率
B9: =IFERROR(SUM(公演データ!$X$3:$X$40)/SUM(公演データ!$R$3:$R$40),"") -> -0.33255982 | C9: =IFERROR(AVERAGE(公演データ!$J$3:$J$40),"") -> 28.945946 | D9: =IFERROR(SUM(公演データ!$R$3:$R$40)/SUM(公演データ!$J$3:$J$40),"") -> 1496.8067 | E9: =IFERROR(AVERAGE(公演データ!$AA$3:$AA$40),"") -> 0.49795796
B12: ■ 直近12公演（実績が入っている公演のみ集計）
B13: 直近12公演 売上 | C13: 直近12公演 粗利 | D13: 直近12公演 平均販売枚数 | E13: 直近12公演 粗利率
B14: =IFERROR(SUM(公演データ!$R$29:$R$40),"") -> 684500 | C14: =IFERROR(SUM(公演データ!$X$29:$X$40),"") -> 94900 | D14: =IFERROR(AVERAGE(公演データ!$J$29:$J$40),"") -> 37.363636 | E14: =IFERROR(SUM(公演データ!$X$29:$X$40)/SUM(公演データ!$R$29:$R$40),"") -> 0.13864134
B17: ■ 決算期別（7月〜翌年6月／GATEの6月決算に合わせた区切り）
B18: 期間 | C18: 公演数 | D18: 販売枚数 | E18: 売上 | F18: コスト | G18: 粗利 | H18: 粗利率
B19: 2023/6期 | C19: =COUNTIFS(公演データ!$C$3:$C$40,">="&DATE(2022,7,1),公演データ!$C$3:$C$40,"<="&DATE(2023,6,30)) -> 1 | D19: =SUMIFS(公演データ!$J$3:$J$40,公演データ!$C$3:$C$40,">="&DATE(2022,7,1),公演データ!$C$3:$C$40,"<="&DATE(2023,6,30)) -> 16 | E19: =SUMIFS(公演データ!$R$3:$R$40,公演データ!$C$3:$C$40,">="&DATE(2022,7,1),公演データ!$C$3:$C$40,"<="&DATE(2023,6,30)) -> 19500 | F19: =SUMIFS(公演データ!$W$3:$W$40,公演データ!$C$3:$C$40,">="&DATE(2022,7,1),公演データ!$C$3:$C$40,"<="&DATE(2023,6,30)) -> 17000 | G19: =SUMIFS(公演データ!$X$3:$X$40,公演データ!$C$3:$C$40,">="&DATE(2022,7,1),公演データ!$C$3:$C$40,"<="&DATE(2023,6,30)) -> 2500 | H19: =IFERROR(G19/E19,"") -> 0.12820513
B20: 2024/6期 | C20: =COUNTIFS(公演データ!$C$3:$C$40,">="&DATE(2023,7,1),公演データ!$C$3:$C$40,"<="&DATE(2024,6,30)) -> 11 | D20: =SUMIFS(公演データ!$J$3:$J$40,公演データ!$C$3:$C$40,">="&DATE(2023,7,1),公演データ!$C$3:$C$40,"<="&DATE(2024,6,30)) -> 298 | E20: =SUMIFS(公演データ!$R$3:$R$40,公演データ!$C$3:$C$40,">="&DATE(2023,7,1),公演データ!$C$3:$C$40,"<="&DATE(2024,6,30)) -> 402580 | F20: =SUMIFS(公演データ!$W$3:$W$40,公演データ!$C$3:$C$40,">="&DATE(2023,7,1),公演データ!$C$3:$C$40,"<="&DATE(2024,6,30)) -> 709000 | G20: =SUMIFS(公演データ!$X$3:$X$40,公演データ!$C$3:$C$40,">="&DATE(2023,7,1),公演データ!$C$3:$C$40,"<="&DATE(2024,6,30)) -> -306420 | H20: =IFERROR(G20/E20,"") -> -0.76114064
B21: 2025/6期 | C21: =COUNTIFS(公演データ!$C$3:$C$40,">="&DATE(2024,7,1),公演データ!$C$3:$C$40,"<="&DATE(2025,6,30)) -> 12 | D21: =SUMIFS(公演データ!$J$3:$J$40,公演データ!$C$3:$C$40,">="&DATE(2024,7,1),公演データ!$C$3:$C$40,"<="&DATE(2025,6,30)) -> 285 | E21: =SUMIFS(公演データ!$R$3:$R$40,公演データ!$C$3:$C$40,">="&DATE(2024,7,1),公演データ!$C$3:$C$40,"<="&DATE(2025,6,30)) -> 414500 | F21: =SUMIFS(公演データ!$W$3:$W$40,公演データ!$C$3:$C$40,">="&DATE(2024,7,1),公演データ!$C$3:$C$40,"<="&DATE(2025,6,30)) -> 717800 | G21: =SUMIFS(公演データ!$X$3:$X$40,公演データ!$C$3:$C$40,">="&DATE(2024,7,1),公演データ!$C$3:$C$40,"<="&DATE(2025,6,30)) -> -303300 | H21: =IFERROR(G21/E21,"") -> -0.73172497
B22: 2026/6期 | C22: =COUNTIFS(公演データ!$C$3:$C$40,">="&DATE(2025,7,1),公演データ!$C$3:$C$40,"<="&DATE(2026,6,30)) -> 12 | D22: =SUMIFS(公演データ!$J$3:$J$40,公演データ!$C$3:$C$40,">="&DATE(2025,7,1),公演データ!$C$3:$C$40,"<="&DATE(2026,6,30)) -> 428 | E22: =SUMIFS(公演データ!$R$3:$R$40,公演データ!$C$3:$C$40,">="&DATE(2025,7,1),公演データ!$C$3:$C$40,"<="&DATE(2026,6,30)) -> 700500 | F22: =SUMIFS(公演データ!$W$3:$W$40,公演データ!$C$3:$C$40,">="&DATE(2025,7,1),公演データ!$C$3:$C$40,"<="&DATE(2026,6,30)) -> 639400 | G22: =SUMIFS(公演データ!$X$3:$X$40,公演データ!$C$3:$C$40,">="&DATE(2025,7,1),公演データ!$C$3:$C$40,"<="&DATE(2026,6,30)) -> 61100 | H22: =IFERROR(G22/E22,"") -> 0.087223412
B23: 2027/6期 | C23: =COUNTIFS(公演データ!$C$3:$C$40,">="&DATE(2026,7,1),公演データ!$C$3:$C$40,"<="&DATE(2027,6,30)) -> 2 | D23: =SUMIFS(公演データ!$J$3:$J$40,公演データ!$C$3:$C$40,">="&DATE(2026,7,1),公演データ!$C$3:$C$40,"<="&DATE(2027,6,30)) -> 44 | E23: =SUMIFS(公演データ!$R$3:$R$40,公演データ!$C$3:$C$40,">="&DATE(2026,7,1),公演データ!$C$3:$C$40,"<="&DATE(2027,6,30)) -> 66000 | F23: =SUMIFS(公演データ!$W$3:$W$40,公演データ!$C$3:$C$40,">="&DATE(2026,7,1),公演データ!$C$3:$C$40,"<="&DATE(2027,6,30)) -> 53000 | G23: =SUMIFS(公演データ!$X$3:$X$40,公演データ!$C$3:$C$40,">="&DATE(2026,7,1),公演データ!$C$3:$C$40,"<="&DATE(2027,6,30)) -> 13000 | H23: =IFERROR(G23/E23,"") -> 0.1969697
B26: ■ 曜日別の傾向（開催曜日の見直し判断に）
B27: 曜日 | C27: 公演数 | D27: 平均販売枚数 | E27: 平均売上 | F27: 平均粗利 | G27: 平均消化率
B28: 月 | C28: =COUNTIF(公演データ!$D$3:$D$40,"月") -> 16 | D28: =IFERROR(AVERAGEIF(公演データ!$D$3:$D$40,"月",公演データ!$J$3:$J$40),"") -> 30.2 | E28: =IFERROR(AVERAGEIF(公演データ!$D$3:$D$40,"月",公演データ!$R$3:$R$40),"") -> 44478.333 | F28: =IFERROR(AVERAGEIF(公演データ!$D$3:$D$40,"月",公演データ!$X$3:$X$40),"") -> -14348.333 | G28: =IFERROR(AVERAGEIF(公演データ!$D$3:$D$40,"月",公演データ!$AA$3:$AA$40),"") -> 0.54729529
B29: 火 | C29: =COUNTIF(公演データ!$D$3:$D$40,"火") -> 5 | D29: =IFERROR(AVERAGEIF(公演データ!$D$3:$D$40,"火",公演データ!$J$3:$J$40),"") -> 35.4 | E29: =IFERROR(AVERAGEIF(公演データ!$D$3:$D$40,"火",公演データ!$R$3:$R$40),"") -> 49800 | F29: =IFERROR(AVERAGEIF(公演データ!$D$3:$D$40,"火",公演データ!$X$3:$X$40),"") -> -7200 | G29: =IFERROR(AVERAGEIF(公演データ!$D$3:$D$40,"火",公演データ!$AA$3:$AA$40),"") -> 0.5842735
B30: 水 | C30: =COUNTIF(公演データ!$D$3:$D$40,"水") -> 3 | D30: =IFERROR(AVERAGEIF(公演データ!$D$3:$D$40,"水",公演データ!$J$3:$J$40),"") -> 13.666667 | E30: =IFERROR(AVERAGEIF(公演データ!$D$3:$D$40,"水",公演データ!$R$3:$R$40),"") -> 20000 | F30: =IFERROR(AVERAGEIF(公演データ!$D$3:$D$40,"水",公演データ!$X$3:$X$40),"") -> -45000 | G30: =IFERROR(AVERAGEIF(公演データ!$D$3:$D$40,"水",公演データ!$AA$3:$AA$40),"") -> 0.26666667
B31: 木 | C31: =COUNTIF(公演データ!$D$3:$D$40,"木") -> 5 | D31: =IFERROR(AVERAGEIF(公演データ!$D$3:$D$40,"木",公演データ!$J$3:$J$40),"") -> 20.4 | E31: =IFERROR(AVERAGEIF(公演データ!$D$3:$D$40,"木",公演データ!$R$3:$R$40),"") -> 28581 | F31: =IFERROR(AVERAGEIF(公演データ!$D$3:$D$40,"木",公演データ!$X$3:$X$40),"") -> -31019 | G31: =IFERROR(AVERAGEIF(公演データ!$D$3:$D$40,"木",公演データ!$AA$3:$AA$40),"") -> 0.41808547
B32: 金 | C32: =COUNTIF(公演データ!$D$3:$D$40,"金") -> 6 | D32: =IFERROR(AVERAGEIF(公演データ!$D$3:$D$40,"金",公演データ!$J$3:$J$40),"") -> 25 | E32: =IFERROR(AVERAGEIF(公演データ!$D$3:$D$40,"金",公演データ!$R$3:$R$40),"") -> 31333.333 | F32: =IFERROR(AVERAGEIF(公演データ!$D$3:$D$40,"金",公演データ!$X$3:$X$40),"") -> -18133.333 | G32: =IFERROR(AVERAGEIF(公演データ!$D$3:$D$40,"金",公演データ!$AA$3:$AA$40),"") -> 0.43629371
B33: 土 | C33: =COUNTIF(公演データ!$D$3:$D$40,"土") -> 1 | D33: =IFERROR(AVERAGEIF(公演データ!$D$3:$D$40,"土",公演データ!$J$3:$J$40),"") -> 14 | E33: =IFERROR(AVERAGEIF(公演データ!$D$3:$D$40,"土",公演データ!$R$3:$R$40),"") -> 21000 | F33: =IFERROR(AVERAGEIF(公演データ!$D$3:$D$40,"土",公演データ!$X$3:$X$40),"") -> -40000 | G33: =IFERROR(AVERAGEIF(公演データ!$D$3:$D$40,"土",公演データ!$AA$3:$AA$40),"") -> 0.35
B34: 日 | C34: =COUNTIF(公演データ!$D$3:$D$40,"日") -> 2 | D34: =IFERROR(AVERAGEIF(公演データ!$D$3:$D$40,"日",公演データ!$J$3:$J$40),"") -> 67 | E34: =IFERROR(AVERAGEIF(公演データ!$D$3:$D$40,"日",公演データ!$R$3:$R$40),"") -> 137500 | F34: =IFERROR(AVERAGEIF(公演データ!$D$3:$D$40,"日",公演データ!$X$3:$X$40),"") -> 78500 | G34: =IFERROR(AVERAGEIF(公演データ!$D$3:$D$40,"日",公演データ!$AA$3:$AA$40),"") -> 0.9375
B37: ■ 顧客（予約者ログより）
B38: 延べ予約者数 | C38: ユニーク顧客数 | D38: リピート予約数 | E38: リピート率
B39: =COUNTIF(予約者ログ!$F$2:$F$600,"新規")+COUNTIF(予約者ログ!$F$2:$F$600,"リピート") -> 0 | C39: =COUNTIF(予約者ログ!$F$2:$F$600,"新規") -> 0 | D39: =COUNTIF(予約者ログ!$F$2:$F$600,"リピート") -> 0 | E39: =IFERROR(COUNTIF(予約者ログ!$F$2:$F$600,"リピート")/(COUNTIF(予約者ログ!$F$2:$F$600,"新規")+COUNTIF(予約者ログ!$F$2:$F$600,"リピート")),"")
B41: ※ 決算期別の期間区切りは7月〜翌6月で設定しています（GATEは6月決算）。
B42: ※ 数値が空欄の項目は、公演データ／予約者ログに実績が未入力です。
B43: ※ コスト（会場費・ゲストギャラ等）が未入力のため、現状の粗利＝売上のまま表示されます。
B81: ■ 集客モデル（アクセス数から着地枚数を予測）
B82: 相関係数 r | C82: 平均CVR | D82: 傾き（1アクセスあたり枚数） | E82: 切片
B83: =IFERROR(CORREL(流入元!$B$2:$B$37,流入元!$H$2:$H$37),"") -> 0.87455426 | C83: =IFERROR(SUM(流入元!$H$2:$H$37)/SUM(流入元!$B$2:$B$37),"") -> 0.048185201 | D83: =IFERROR(流入元!$M$1,"") -> 0.043858367 | E83: =IFERROR(流入元!$N$1,"") -> 2.4868481
B85: 次回公演のシミュレーション
B86: 販売上限（枚） | C86: 見込みアクセス数 | D86: 予測枚数 | E86: 上限を埋めるのに必要なアクセス
B87: 65 | C87: 900 | D87: =IFERROR(MIN(B87,ROUND(流入元!$M$1*C87+流入元!$N$1,0)),"") -> 42 | E87: =IFERROR(ROUND((B87-流入元!$N$1)/流入元!$M$1,0),"") -> 1425
B89: ※ 黄色の2セル（販売上限・見込みアクセス数）を入れると、着地枚数と必要アクセスが出ます。
B90: ※ このモデルはvol.33を除く公演の実績に基づく回帰。CVRが安定している前提での目安です。

Sheet ガイド
B1: YAGATE LIVE 収益管理ダッシュボード
B2: 公演ごとの収支・動員・顧客を1枚で管理し、ダッシュボードで自動集計します。
B4: ■ 共通設定（先にここを埋める）
B5: 項目 | C5: 値 | D5: 説明
B6: チケット決済手数料率 | C6: 0 | D6: Tiget等の販売手数料率。公演データの「決済手数料」列が自動計算されます。
B7: 目標粗利率 | C7: 0.3 | D7: ダッシュボードの判定ラインに使用。
B8: 月あたり固定費配賦額 | C8: 0 | D8: ライブ運営に按分する人件費等があれば入力（無ければ0）。
B9: ゲスト1組あたりギャラ | C9: 4000 | D9: 実額が未入力の公演で「ゲスト組数×この額」を自動計算。
B10: 標準制作・運営費 | C10: 4000 | D10: 学生スタッフ等。実額が未入力の公演に適用（直近実績3,000〜4,000円）。
B12: ■ 色の凡例
B13: 青字・黄色セル | C13: 手入力する箇所。ここだけ埋めればOK。
B14: 黒字 | C14: 自動計算（数式）。上書きしないでください。
B15: 緑字 | C15: 他シートからの参照。
B17: ■ 使い方（毎公演の運用）
B18: 1. 公演終了後、「公演データ」シートの黄色セルに実績を入力（動員数・各売上・各コスト）。
B19: 2. Tigetの予約者CSVを「予約者ログ」シートに追記（公演回とメールアドレス等の識別子）。
B20: 3. 「ダッシュボード」シートは自動更新。数式に触れる必要はありません。
B21: 4. 新しい会場を使う場合は「会場マスタ」に会場名とキャパを追加してから公演データで選択。
B23: ■ 記入例（この形式で入力してください）
B24: チケット単価 | C24: 販売上限 | D24: 販売枚数 | E24: 実来場数 | F24: 物販売上 | G24: 会場費 | H24: ゲストギャラ
B25: 1500 | C25: 65 | D25: 44 | E25: 41 | F25: 24000 | G25: 45000 | H25: 30000
B26: ※ 上記はフォーマット確認用のダミー値です（実績ではありません）。
B28: ■ データ出典
B29: 公演一覧（回数・開催日・曜日・出演者）はユーザー提供の一覧表（yagate.jp アーカイブ）に基づく。
B30: vol.29〜37の販売上限・販売枚数はTiget管理画面より転記。会場名は一部に誤りがあるとの申告あり（E列で修正可）。

Sheet 会場マスタ
A1: 会場名 | B1: キャパ（席） | C1: 標準会場費 | D1: メモ
A2: 新宿ハイジアV-1 | C2: 45000 | D2: 標準会場費。実績42,800円（5公演平均）
A3: 下北沢シアターミネルヴァ | C3: 30000 | D3: 標準会場費。実績31,667円（3公演平均）
A4: 渋谷ばぐちか | C4: 0 | D4: vol.1のみ。音響トラブルのため会場費0
A14: ※ 標準会場費は「公演データ」S列に自動反映されます（実額を入力した公演は実額が優先）。
A15: ※ 会場名は「公演データ」E列と完全一致させてください。E列を正しい会場に直せば、会場費が自動で入ります。

Sheet 公演データ
A1: 基本情報 | I1: 動員 | L1: 売上（入力） | S1: コスト（入力） | X1: 指標（自動）
A2: 回数 | B2: 公演名 | C2: 開催日 | D2: 曜日 | E2: 会場 | F2: 販売上限 （枚） | G2: 出演者・ゲスト | H2: 出演組数 | I2: チケット単価 | J2: 販売枚数 （予約） | K2: 実来場数 | L2: チケット売上 | M2: その他チケット収入 | N2: 物販売上 | O2: 特典会売上 | P2: 配信売上 | Q2: 協賛売上 | R2: 売上合計 | S2: 会場費 | T2: ゲストギャラ | U2: 制作・運営費 | V2: 決済手数料 | W2: コスト合計 | X2: 粗利 | Y2: 粗利率 | Z2: 客単価 | AA2: 消化率 | AB2: キャンセル率 | AC2: 損益分岐動員数 | AD2: 備考 | AI2: ゲスト組数
A3: vol.1 | B3: YAGATE vol.1 | C3: 45079 | D3: 金 | E3: 渋谷ばぐちか | F3: 110 | G3: 友田オレ／リンドバーグ／ジグロポッカ／ミスター大冒険。／いろはラムネ／シノブ／高田ぽる子 | H3: =IF(G3="","",LEN(G3)-LEN(SUBSTITUTE(G3,"／",""))+1) -> 7 | I3: 1500 | J3: 16 | L3: 19500 | R3: =IF(COUNT(L3:Q3)=0,"",SUM(L3:Q3)) -> 19500 | S3: 0 | T3: 12000 | U3: 5000 | V3: =IF(L3="","",ROUND(L3*ガイド!$C$6,0)) -> 0 | W3: =IF(COUNT(S3:V3)=0,"",SUM(S3:V3)) -> 17000 | X3: =IF(AND(R3="",W3=""),"",SUM(R3)-SUM(W3)) -> 2500 | Y3: =IFERROR(X3/R3,"") -> 0.12820513 | Z3: =IFERROR(R3/J3,"") -> 1218.75 | AA3: =IF(OR(J3="",F3=""),"",IFERROR(J3/F3,"")) -> 0.14545455 | AB3: =IFERROR((J3-K3)/J3,"") -> 1 | AC3: =IFERROR(ROUNDUP(W3/I3,0),"") -> 12 | AD3: Tiget予約枚数／単価1,500円（実収支データより確認） | AI3: 5
A4: vol.2 | B4: YAGATE vol.2 | C4: 45133 | D4: 水 | E4: 新宿ハイジアV-1 | F4: 60 | G4: 友田オレ／リンドバーグ／チュランペット／金魚番長／青御膳／えびしゃ | H4: =IF(G4="","",LEN(G4)-LEN(SUBSTITUTE(G4,"／",""))+1) -> 6 | I4: 1500 | J4: 13 | L4: 18000 | R4: =IF(COUNT(L4:Q4)=0,"",SUM(L4:Q4)) -> 18000 | S4: 43000 | T4: 12000 | U4: 10000 | V4: =IF(L4="","",ROUND(L4*ガイド!$C$6,0)) -> 0 | W4: =IF(COUNT(S4:V4)=0,"",SUM(S4:V4)) -> 65000 | X4: =IF(AND(R4="",W4=""),"",SUM(R4)-SUM(W4)) -> -47000 | Y4: =IFERROR(X4/R4,"") -> -2.6111111 | Z4: =IFERROR(R4/J4,"") -> 1384.6154 | AA4: =IF(OR(J4="",F4=""),"",IFERROR(J4/F4,"")) -> 0.21666667 | AB4: =IFERROR((J4-K4)/J4,"") -> 1 | AC4: =IFERROR(ROUNDUP(W4/I4,0),"") -> 44 | AD4: Tiget予約枚数／単価1,500円（実収支データより確認） | AI4: 4
A5: vol.3 | B5: YAGATE vol.3 | C5: 45159 | D5: 月 | E5: 新宿ハイジアV-1 | F5: 60 | G5: 友田オレ／リンドバーグ／ツンツクツン万博／清水駿平／ゼンモンキー／兄弟／豆鉄砲 | H5: =IF(G5="","",LEN(G5)-LEN(SUBSTITUTE(G5,"／",""))+1) -> 7 | I5: 1500 | J5: 30 | L5: =IF(OR(I5="",J5=""),"",I5*J5) -> 45000 | M5: 3175 | R5: =IF(COUNT(L5:Q5)=0,"",SUM(L5:Q5)) -> 48175 | S5: 43000 | T5: 20000 | U5: 9000 | V5: =IF(L5="","",ROUND(L5*ガイド!$C$6,0)) -> 0 | W5: =IF(COUNT(S5:V5)=0,"",SUM(S5:V5)) -> 72000 | X5: =IF(AND(R5="",W5=""),"",SUM(R5)-SUM(W5)) -> -23825 | Y5: =IFERROR(X5/R5,"") -> -0.49455112 | Z5: =IFERROR(R5/J5,"") -> 1605.8333 | AA5: =IF(OR(J5="",F5=""),"",IFERROR(J5/F5,"")) -> 0.5 | AB5: =IFERROR((J5-K5)/J5,"") -> 1 | AC5: =IFERROR(ROUNDUP(W5/I5,0),"") -> 48 | AD5: Tiget予約枚数／単価1,500円（実収支データより確認） | AI5: 5
A6: vol.4 | B6: YAGATE vol.4 | C6: 45190 | D6: 木 | E6: 下北沢シアターミネルヴァ | F6: 30 | G6: 友田オレ／リンドバーグ／徳原旅行／鈴木ジェロニモ／鉛筆ドリル／惹女香花／ハマタ残機ゼロ | H6: =IF(G6="","",LEN(G6)-LEN(SUBSTITUTE(G6,"／",""))+1) -> 7 | I6: 1500 | J6: 16 | L6: 22500 | M6: 1905 | R6: =IF(COUNT(L6:Q6)=0,"",SUM(L6:Q6)) -> 24405 | S6: 35000 | T6: 14000 | U6: 9000 | V6: =IF(L6="","",ROUND(L6*ガイド!$C$6,0)) -> 0 | W6: =IF(COUNT(S6:V6)=0,"",SUM(S6:V6)) -> 58000 | X6: =IF(AND(R6="",W6=""),"",SUM(R6)-SUM(W6)) -> -33595 | Y6: =IFERROR(X6/R6,"") -> -1.3765622 | Z6: =IFERROR(R6/J6,"") -> 1525.3125 | AA6: =IF(OR(J6="",F6=""),"",IFERROR(J6/F6,"")) -> 0.53333333 | AB6: =IFERROR((J6-K6)/J6,"") -> 1 | AC6: =IFERROR(ROUNDUP(W6/I6,0),"") -> 39 | AD6: Tiget予約枚数／単価1,500円（実収支データより確認） | AI6: 5
A7: vol.5 | B7: YAGATE vol.5 | C7: 45229 | D7: 月 | E7: 新宿ハイジアV-1 | F7: 50 | G7: 友田オレ／リンドバーグ／フランツ／人間横丁／キャプテンバイソン／坊屋／伝書鳩 | H7: =IF(G7="","",LEN(G7)-LEN(SUBSTITUTE(G7,"／",""))+1) -> 7 | I7: 1500 | J7: 25 | L7: 37500 | R7: =IF(COUNT(L7:Q7)=0,"",SUM(L7:Q7)) -> 37500 | S7: 43000 | T7: 18000 | U7: 9000 | V7: =IF(L7="","",ROUND(L7*ガイド!$C$6,0)) -> 0 | W7: =IF(COUNT(S7:V7)=0,"",SUM(S7:V7)) -> 70000 | X7: =IF(AND(R7="",W7=""),"",SUM(R7)-SUM(W7)) -> -32500 | Y7: =IFERROR(X7/R7,"") -> -0.86666667 | Z7: =IFERROR(R7/J7,"") -> 1500 | AA7: =IF(OR(J7="",F7=""),"",IFERROR(J7/F7,"")) -> 0.5 | AB7: =IFERROR((J7-K7)/J7,"") -> 1 | AC7: =IFERROR(ROUNDUP(W7/I7,0),"") -> 47 | AD7: Tiget予約枚数／単価1,500円（実収支データより確認） | AI7: 5
A8: vol.6 | B8: YAGATE vol.6 | C8: 45257 | D8: 月 | E8: 新宿ハイジアV-1 | F8: 60 | G8: 友田オレ／リンドバーグ／破壊ありがとう／モシモシ／江戸マリー／無尽蔵 | H8: =IF(G8="","",LEN(G8)-LEN(SUBSTITUTE(G8,"／",""))+1) -> 6 | I8: 1500 | J8: 19 | L8: =IF(OR(I8="",J8=""),"",I8*J8) -> 28500 | R8: =IF(COUNT(L8:Q8)=0,"",SUM(L8:Q8)) -> 28500 | S8: =IFERROR(INDEX(会場マスタ!$C$2:$C$12,MATCH(E8,会場マスタ!$A$2:$A$12,0)),"") -> 45000 | T8: =IF(AI8="","",AI8*ガイド!$C$9) -> 16000 | U8: =ガイド!$C$10 -> 4000 | V8: =IF(L8="","",ROUND(L8*ガイド!$C$6,0)) -> 0 | W8: =IF(COUNT(S8:V8)=0,"",SUM(S8:V8)) -> 65000 | X8: =IF(AND(R8="",W8=""),"",SUM(R8)-SUM(W8)) -> -36500 | Y8: =IFERROR(X8/R8,"") -> -1.2807018 | Z8: =IFERROR(R8/J8,"") -> 1500 | AA8: =IF(OR(J8="",F8=""),"",IFERROR(J8/F8,"")) -> 0.31666667 | AB8: =IFERROR((J8-K8)/J8,"") -> 1 | AC8: =IFERROR(ROUNDUP(W8/I8,0),"") -> 44 | AD8: Tiget予約枚数／単価1,500円（実収支データより確認） | AI8: 4
A9: vol.7 | B9: YAGATE vol.7 | C9: 45280 | D9: 水 | E9: 新宿ハイジアV-1 | F9: 60 | G9: 友田オレ／リンドバーグ／サスペンダーズ／いろはラムネ／美魔女／鈴木ジェロニモ／ラパルフェ | H9: =IF(G9="","",LEN(G9)-LEN(SUBSTITUTE(G9,"／",""))+1) -> 7 | I9: 1500 | J9: 14 | L9: =IF(OR(I9="",J9=""),"",I9*J9) -> 21000 | R9: =IF(COUNT(L9:Q9)=0,"",SUM(L9:Q9)) -> 21000 | S9: =IFERROR(INDEX(会場マスタ!$C$2:$C$12,MATCH(E9,会場マスタ!$A$2:$A$12,0)),"") -> 45000 | T9: =IF(AI9="","",AI9*ガイド!$C$9) -> 20000 | U9: =ガイド!$C$10 -> 4000 | V9: =IF(L9="","",ROUND(L9*ガイド!$C$6,0)) -> 0 | W9: =IF(COUNT(S9:V9)=0,"",SUM(S9:V9)) -> 69000 | X9: =IF(AND(R9="",W9=""),"",SUM(R9)-SUM(W9)) -> -48000 | Y9: =IFERROR(X9/R9,"") -> -2.2857143 | Z9: =IFERROR(R9/J9,"") -> 1500 | AA9: =IF(OR(J9="",F9=""),"",IFERROR(J9/F9,"")) -> 0.23333333 | AB9: =IFERROR((J9-K9)/J9,"") -> 1 | AC9: =IFERROR(ROUNDUP(W9/I9,0),"") -> 46 | AD9: Tiget予約枚数／単価1,500円（実収支データより確認） | AI9: 5
A10: vol.8 | B10: YAGATE vol.8 | C10: 45340 | D10: 日 | E10: 新宿ハイジアV-1 | F10: 64 | G10: 友田オレ／リンドバーグ／徳原旅行／清水駿平／鉛筆ドリル／ナユタ | H10: =IF(G10="","",LEN(G10)-LEN(SUBSTITUTE(G10,"／",""))+1) -> 6 | I10: 1500 | J10: 60 | L10: =IF(OR(I10="",J10=""),"",I10*J10) -> 90000 | R10: =IF(COUNT(L10:Q10)=0,"",SUM(L10:Q10)) -> 90000 | S10: =IFERROR(INDEX(会場マスタ!$C$2:$C$12,MATCH(E10,会場マスタ!$A$2:$A$12,0)),"") -> 45000 | T10: =IF(AI10="","",AI10*ガイド!$C$9) -> 16000 | U10: =ガイド!$C$10 -> 4000 | V10: =IF(L10="","",ROUND(L10*ガイド!$C$6,0)) -> 0 | W10: =IF(COUNT(S10:V10)=0,"",SUM(S10:V10)) -> 65000 | X10: =IF(AND(R10="",W10=""),"",SUM(R10)-SUM(W10)) -> 25000 | Y10: =IFERROR(X10/R10,"") -> 0.27777778 | Z10: =IFERROR(R10/J10,"") -> 1500 | AA10: =IF(OR(J10="",F10=""),"",IFERROR(J10/F10,"")) -> 0.9375 | AB10: =IFERROR((J10-K10)/J10,"") -> 1 | AC10: =IFERROR(ROUNDUP(W10/I10,0),"") -> 44 | AD10: 一般39/42＋学生21/22。単価は推定 | AI10: 4
A11: vol.9 | B11: YAGATE vol.9 | C11: 45369 | D11: 月 | E11: 新宿ハイジアV-1 | F11: 65 | G11: 友田オレ／リンドバーグ／ツンツクツン万博／都トム／兄弟／サノライブ | H11: =IF(G11="","",LEN(G11)-LEN(SUBSTITUTE(G11,"／",""))+1) -> 6 | I11: 1500 | J11: 42 | L11: =IF(OR(I11="",J11=""),"",I11*J11) -> 63000 | R11: =IF(COUNT(L11:Q11)=0,"",SUM(L11:Q11)) -> 63000 | S11: =IFERROR(INDEX(会場マスタ!$C$2:$C$12,MATCH(E11,会場マスタ!$A$2:$A$12,0)),"") -> 45000 | T11: =IF(AI11="","",AI11*ガイド!$C$9) -> 16000 | U11: =ガイド!$C$10 -> 4000 | V11: =IF(L11="","",ROUND(L11*ガイド!$C$6,0)) -> 0 | W11: =IF(COUNT(S11:V11)=0,"",SUM(S11:V11)) -> 65000 | X11: =IF(AND(R11="",W11=""),"",SUM(R11)-SUM(W11)) -> -2000 | Y11: =IFERROR(X11/R11,"") -> -0.031746032 | Z11: =IFERROR(R11/J11,"") -> 1500 | AA11: =IF(OR(J11="",F11=""),"",IFERROR(J11/F11,"")) -> 0.64615385 | AB11: =IFERROR((J11-K11)/J11,"") -> 1 | AC11: =IFERROR(ROUNDUP(W11/I11,0),"") -> 44 | AD11: 一般25/40＋学生17/25。単価は推定 | AI11: 4
A12: vol.10 | B12: YAGATE vol.10 | C12: 45401 | D12: 金 | E12: 新宿ハイジアV-1 | F12: 65 | G12: 友田オレ／リンドバーグ／イクラボブチャンチャン／坊屋／十九人／わっきゃい | H12: =IF(G12="","",LEN(G12)-LEN(SUBSTITUTE(G12,"／",""))+1) -> 6 | I12: 1000 | J12: 32 | L12: 18000 | R12: =IF(COUNT(L12:Q12)=0,"",SUM(L12:Q12)) -> 18000 | S12: 40000 | T12: 14000 | U12: 4000 | V12: =IF(L12="","",ROUND(L12*ガイド!$C$6,0)) -> 0 | W12: =IF(COUNT(S12:V12)=0,"",SUM(S12:V12)) -> 58000 | X12: =IF(AND(R12="",W12=""),"",SUM(R12)-SUM(W12)) -> -40000 | Y12: =IFERROR(X12/R12,"") -> -2.2222222 | Z12: =IFERROR(R12/J12,"") -> 562.5 | AA12: =IF(OR(J12="",F12=""),"",IFERROR(J12/F12,"")) -> 0.49230769 | AB12: =IFERROR((J12-K12)/J12,"") -> 1 | AC12: =IFERROR(ROUNDUP(W12/I12,0),"") -> 58 | AD12: 一般1,000円 | AI12: 3
A13: vol.11 | B13: YAGATE vol.11 | C13: 45440 | D13: 火 | E13: 新宿ハイジアV-1 | F13: 65 | G13: 友田オレ／リンドバーグ／イクラボブチャンチャン | H13: =IF(G13="","",LEN(G13)-LEN(SUBSTITUTE(G13,"／",""))+1) -> 3 | I13: 1000 | J13: 33 | L13: =IF(OR(I13="",J13=""),"",I13*J13) -> 33000 | R13: =IF(COUNT(L13:Q13)=0,"",SUM(L13:Q13)) -> 33000 | S13: =IFERROR(INDEX(会場マスタ!$C$2:$C$12,MATCH(E13,会場マスタ!$A$2:$A$12,0)),"") -> 45000 | T13: =IF(AI13="","",AI13*ガイド!$C$9) -> 12000 | U13: =ガイド!$C$10 -> 4000 | V13: =IF(L13="","",ROUND(L13*ガイド!$C$6,0)) -> 0 | W13: =IF(COUNT(S13:V13)=0,"",SUM(S13:V13)) -> 61000 | X13: =IF(AND(R13="",W13=""),"",SUM(R13)-SUM(W13)) -> -28000 | Y13: =IFERROR(X13/R13,"") -> -0.84848485 | Z13: =IFERROR(R13/J13,"") -> 1000 | AA13: =IF(OR(J13="",F13=""),"",IFERROR(J13/F13,"")) -> 0.50769231 | AB13: =IFERROR((J13-K13)/J13,"") -> 1 | AC13: =IFERROR(ROUNDUP(W13/I13,0),"") -> 61 | AD13: 一般1,000円 | AI13: 3
A14: vol.12 | B14: YAGATE vol.12 | C14: 45472 | D14: 土 | E14: 新宿ハイジアV-1 | F14: 40 | G14: 友田オレ／リンドバーグ／イクラボブチャンチャン | H14: =IF(G14="","",LEN(G14)-LEN(SUBSTITUTE(G14,"／",""))+1) -> 3 | I14: 1500 | J14: 14 | L14: =IF(OR(I14="",J14=""),"",I14*J14) -> 21000 | R14: =IF(COUNT(L14:Q14)=0,"",SUM(L14:Q14)) -> 21000 | S14: =IFERROR(INDEX(会場マスタ!$C$2:$C$12,MATCH(E14,会場マスタ!$A$2:$A$12,0)),"") -> 45000 | T14: =IF(AI14="","",AI14*ガイド!$C$9) -> 12000 | U14: =ガイド!$C$10 -> 4000 | V14: =IF(L14="","",ROUND(L14*ガイド!$C$6,0)) -> 0 | W14: =IF(COUNT(S14:V14)=0,"",SUM(S14:V14)) -> 61000 | X14: =IF(AND(R14="",W14=""),"",SUM(R14)-SUM(W14)) -> -40000 | Y14: =IFERROR(X14/R14,"") -> -1.9047619 | Z14: =IFERROR(R14/J14,"") -> 1500 | AA14: =IF(OR(J14="",F14=""),"",IFERROR(J14/F14,"")) -> 0.35 | AB14: =IFERROR((J14-K14)/J14,"") -> 1 | AC14: =IFERROR(ROUNDUP(W14/I14,0),"") -> 41 | AD14: 開演20:00 | AI14: 3
A15: vol.13 | B15: YAGATE vol.13 | C15: 45498 | D15: 木 | E15: 新宿ハイジアV-1 | F15: 65 | G15: 友田オレ／リンドバーグ／イクラボブチャンチャン | H15: =IF(G15="","",LEN(G15)-LEN(SUBSTITUTE(G15,"／",""))+1) -> 3 | I15: 1500 | J15: 22 | L15: 22500 | R15: =IF(COUNT(L15:Q15)=0,"",SUM(L15:Q15)) -> 22500 | S15: 45000 | T15: 12000 | U15: 4000 | V15: =IF(L15="","",ROUND(L15*ガイド!$C$6,0)) -> 0 | W15: =IF(COUNT(S15:V15)=0,"",SUM(S15:V15)) -> 61000 | X15: =IF(AND(R15="",W15=""),"",SUM(R15)-SUM(W15)) -> -38500 | Y15: =IFERROR(X15/R15,"") -> -1.7111111 | Z15: =IFERROR(R15/J15,"") -> 1022.7273 | AA15: =IF(OR(J15="",F15=""),"",IFERROR(J15/F15,"")) -> 0.33846154 | AB15: =IFERROR((J15-K15)/J15,"") -> 1 | AC15: =IFERROR(ROUNDUP(W15/I15,0),"") -> 41 | AD15: Tiget予約枚数 | AI15: 3
A16: vol.14 | B16: YAGATE vol.14 | C16: 45533 | D16: 木 | E16: 新宿ハイジアV-1 | F16: 45 | G16: 友田オレ／リンドバーグ／イクラボブチャンチャン | H16: =IF(G16="","",LEN(G16)-LEN(SUBSTITUTE(G16,"／",""))+1) -> 3 | I16: 1500 | J16: 16 | L16: =IF(OR(I16="",J16=""),"",I16*J16) -> 24000 | R16: =IF(COUNT(L16:Q16)=0,"",SUM(L16:Q16)) -> 24000 | S16: =IFERROR(INDEX(会場マスタ!$C$2:$C$12,MATCH(E16,会場マスタ!$A$2:$A$12,0)),"") -> 45000 | T16: =IF(AI16="","",AI16*ガイド!$C$9) -> 12000 | U16: =ガイド!$C$10 -> 4000 | V16: =IF(L16="","",ROUND(L16*ガイド!$C$6,0)) -> 0 | W16: =IF(COUNT(S16:V16)=0,"",SUM(S16:V16)) -> 61000 | X16: =IF(AND(R16="",W16=""),"",SUM(R16)-SUM(W16)) -> -37000 | Y16: =IFERROR(X16/R16,"") -> -1.5416667 | Z16: =IFERROR(R16/J16,"") -> 1500 | AA16: =IF(OR(J16="",F16=""),"",IFERROR(J16/F16,"")) -> 0.35555556 | AB16: =IFERROR((J16-K16)/J16,"") -> 1 | AC16: =IFERROR(ROUNDUP(W16/I16,0),"") -> 41 | AD16: Tiget予約枚数 | AI16: 3
A17: vol.15 | B17: YAGATE vol.15 | C17: 45565 | D17: 月 | E17: 新宿ハイジアV-1 | F17: 65 | G17: 友田オレ／リンドバーグ／イクラボブチャンチャン | H17: =IF(G17="","",LEN(G17)-LEN(SUBSTITUTE(G17,"／",""))+1) -> 3 | I17: 1500 | J17: 38 | L17: =IF(OR(I17="",J17=""),"",I17*J17) -> 57000 | R17: =IF(COUNT(L17:Q17)=0,"",SUM(L17:Q17)) -> 57000 | S17: =IFERROR(INDEX(会場マスタ!$C$2:$C$12,MATCH(E17,会場マスタ!$A$2:$A$12,0)),"") -> 45000 | T17: =IF(AI17="","",AI17*ガイド!$C$9) -> 12000 | U17: =ガイド!$C$10 -> 4000 | V17: =IF(L17="","",ROUND(L17*ガイド!$C$6,0)) -> 0 | W17: =IF(COUNT(S17:V17)=0,"",SUM(S17:V17)) -> 61000 | X17: =IF(AND(R17="",W17=""),"",SUM(R17)-SUM(W17)) -> -4000 | Y17: =IFERROR(X17/R17,"") -> -0.070175439 | Z17: =IFERROR(R17/J17,"") -> 1500 | AA17: =IF(OR(J17="",F17=""),"",IFERROR(J17/F17,"")) -> 0.58461538 | AB17: =IFERROR((J17-K17)/J17,"") -> 1 | AC17: =IFERROR(ROUNDUP(W17/I17,0),"") -> 41 | AD17: Tiget予約枚数 | AI17: 3
A18: vol.16 | B18: YAGATE vol.16 | C18: 45583 | D18: 金 | E18: 下北沢シアターミネルヴァ | F18: 65 | G18: 友田オレ／リンドバーグ／イクラボブチャンチャン | H18: =IF(G18="","",LEN(G18)-LEN(SUBSTITUTE(G18,"／",""))+1) -> 3 | I18: 1500 | J18: 13 | L18: 17000 | R18: =IF(COUNT(L18:Q18)=0,"",SUM(L18:Q18)) -> 17000 | S18: 30000 | T18: 16800 | U18: 4000 | V18: =IF(L18="","",ROUND(L18*ガイド!$C$6,0)) -> 0 | W18: =IF(COUNT(S18:V18)=0,"",SUM(S18:V18)) -> 50800 | X18: =IF(AND(R18="",W18=""),"",SUM(R18)-SUM(W18)) -> -33800 | Y18: =IFERROR(X18/R18,"") -> -1.9882353 | Z18: =IFERROR(R18/J18,"") -> 1307.6923 | AA18: =IF(OR(J18="",F18=""),"",IFERROR(J18/F18,"")) -> 0.2 | AB18: =IFERROR((J18-K18)/J18,"") -> 1 | AC18: =IFERROR(ROUNDUP(W18/I18,0),"") -> 34 | AD18: Tiget予約枚数 | AI18: 3
A19: vol.17 | B19: YAGATE vol.17 | C19: 45622 | D19: 火 | E19: 新宿ハイジアV-1 | F19: 65 | G19: 友田オレ／リンドバーグ／イクラボブチャンチャン | H19: =IF(G19="","",LEN(G19)-LEN(SUBSTITUTE(G19,"／",""))+1) -> 3 | I19: 1500 | J19: 32 | L19: =IF(OR(I19="",J19=""),"",I19*J19) -> 48000 | R19: =IF(COUNT(L19:Q19)=0,"",SUM(L19:Q19)) -> 48000 | S19: =IFERROR(INDEX(会場マスタ!$C$2:$C$12,MATCH(E19,会場マスタ!$A$2:$A$12,0)),"") -> 45000 | T19: =IF(AI19="","",AI19*ガイド!$C$9) -> 12000 | U19: =ガイド!$C$10 -> 4000 | V19: =IF(L19="","",ROUND(L19*ガイド!$C$6,0)) -> 0 | W19: =IF(COUNT(S19:V19)=0,"",SUM(S19:V19)) -> 61000 | X19: =IF(AND(R19="",W19=""),"",SUM(R19)-SUM(W19)) -> -13000 | Y19: =IFERROR(X19/R19,"") -> -0.27083333 | Z19: =IFERROR(R19/J19,"") -> 1500 | AA19: =IF(OR(J19="",F19=""),"",IFERROR(J19/F19,"")) -> 0.49230769 | AB19: =IFERROR((J19-K19)/J19,"") -> 1 | AC19: =IFERROR(ROUNDUP(W19/I19,0),"") -> 41 | AD19: Tiget予約枚数 | AI19: 3
A20: vol.18 | B20: YAGATE vol.18 | C20: 45642 | D20: 月 | E20: 新宿ハイジアV-1 | F20: 40 | G20: 友田オレ／リンドバーグ／イクラボブチャンチャン | H20: =IF(G20="","",LEN(G20)-LEN(SUBSTITUTE(G20,"／",""))+1) -> 3 | I20: 1500 | J20: 11 | L20: =IF(OR(I20="",J20=""),"",I20*J20) -> 16500 | R20: =IF(COUNT(L20:Q20)=0,"",SUM(L20:Q20)) -> 16500 | S20: =IFERROR(INDEX(会場マスタ!$C$2:$C$12,MATCH(E20,会場マスタ!$A$2:$A$12,0)),"") -> 45000 | T20: =IF(AI20="","",AI20*ガイド!$C$9) -> 12000 | U20: =ガイド!$C$10 -> 4000 | V20: =IF(L20="","",ROUND(L20*ガイド!$C$6,0)) -> 0 | W20: =IF(COUNT(S20:V20)=0,"",SUM(S20:V20)) -> 61000 | X20: =IF(AND(R20="",W20=""),"",SUM(R20)-SUM(W20)) -> -44500 | Y20: =IFERROR(X20/R20,"") -> -2.6969697 | Z20: =IFERROR(R20/J20,"") -> 1500 | AA20: =IF(OR(J20="",F20=""),"",IFERROR(J20/F20,"")) -> 0.275 | AB20: =IFERROR((J20-K20)/J20,"") -> 1 | AC20: =IFERROR(ROUNDUP(W20/I20,0),"") -> 41 | AD20: Tiget予約枚数 | AI20: 3
A21: vol.19 | B21: YAGATE vol.19 | C21: 45687 | D21: 木 | E21: 新宿ハイジアV-1 | F21: 65 | G21: 友田オレ／リンドバーグ／イクラボブチャンチャン | H21: =IF(G21="","",LEN(G21)-LEN(SUBSTITUTE(G21,"／",""))+1) -> 3 | I21: 1500 | J21: 21 | L21: =IF(OR(I21="",J21=""),"",I21*J21) -> 31500 | R21: =IF(COUNT(L21:Q21)=0,"",SUM(L21:Q21)) -> 31500 | S21: =IFERROR(INDEX(会場マスタ!$C$2:$C$12,MATCH(E21,会場マスタ!$A$2:$A$12,0)),"") -> 45000 | T21: =IF(AI21="","",AI21*ガイド!$C$9) -> 12000 | U21: =ガイド!$C$10 -> 4000 | V21: =IF(L21="","",ROUND(L21*ガイド!$C$6,0)) -> 0 | W21: =IF(COUNT(S21:V21)=0,"",SUM(S21:V21)) -> 61000 | X21: =IF(AND(R21="",W21=""),"",SUM(R21)-SUM(W21)) -> -29500 | Y21: =IFERROR(X21/R21,"") -> -0.93650794 | Z21: =IFERROR(R21/J21,"") -> 1500 | AA21: =IF(OR(J21="",F21=""),"",IFERROR(J21/F21,"")) -> 0.32307692 | AB21: =IFERROR((J21-K21)/J21,"") -> 1 | AC21: =IFERROR(ROUNDUP(W21/I21,0),"") -> 41 | AD21: Tiget予約枚数 | AI21: 3
A22: vol.20 | B22: YAGATE vol.20 | C22: 45705 | D22: 月 | E22: 新宿ハイジアV-1 | F22: 40 | G22: 友田オレ／リンドバーグ／イクラボブチャンチャン | H22: =IF(G22="","",LEN(G22)-LEN(SUBSTITUTE(G22,"／",""))+1) -> 3 | I22: 1500 | J22: 19 | L22: =IF(OR(I22="",J22=""),"",I22*J22) -> 28500 | R22: =IF(COUNT(L22:Q22)=0,"",SUM(L22:Q22)) -> 28500 | S22: =IFERROR(INDEX(会場マスタ!$C$2:$C$12,MATCH(E22,会場マスタ!$A$2:$A$12,0)),"") -> 45000 | T22: =IF(AI22="","",AI22*ガイド!$C$9) -> 12000 | U22: =ガイド!$C$10 -> 4000 | V22: =IF(L22="","",ROUND(L22*ガイド!$C$6,0)) -> 0 | W22: =IF(COUNT(S22:V22)=0,"",SUM(S22:V22)) -> 61000 | X22: =IF(AND(R22="",W22=""),"",SUM(R22)-SUM(W22)) -> -32500 | Y22: =IFERROR(X22/R22,"") -> -1.1403509 | Z22: =IFERROR(R22/J22,"") -> 1500 | AA22: =IF(OR(J22="",F22=""),"",IFERROR(J22/F22,"")) -> 0.475 | AB22: =IFERROR((J22-K22)/J22,"") -> 1 | AC22: =IFERROR(ROUNDUP(W22/I22,0),"") -> 41 | AD22: Tiget予約枚数 | AI22: 3
A23: vol.21 | B23: YAGATE vol.21 | C23: 45747 | D23: 月 | E23: 新宿ハイジアV-1 | F23: 62 | G23: 友田オレ／リンドバーグ／イクラボブチャンチャン／シャワーカーテニスト | H23: =IF(G23="","",LEN(G23)-LEN(SUBSTITUTE(G23,"／",""))+1) -> 4 | I23: 1500 | J23: 54 | L23: =IF(OR(I23="",J23=""),"",I23*J23) -> 81000 | R23: =IF(COUNT(L23:Q23)=0,"",SUM(L23:Q23)) -> 81000 | S23: =IFERROR(INDEX(会場マスタ!$C$2:$C$12,MATCH(E23,会場マスタ!$A$2:$A$12,0)),"") -> 45000 | T23: =IF(AI23="","",AI23*ガイド!$C$9) -> 12000 | U23: =ガイド!$C$10 -> 4000 | V23: =IF(L23="","",ROUND(L23*ガイド!$C$6,0)) -> 0 | W23: =IF(COUNT(S23:V23)=0,"",SUM(S23:V23)) -> 61000 | X23: =IF(AND(R23="",W23=""),"",SUM(R23)-SUM(W23)) -> 20000 | Y23: =IFERROR(X23/R23,"") -> 0.24691358 | Z23: =IFERROR(R23/J23,"") -> 1500 | AA23: =IF(OR(J23="",F23=""),"",IFERROR(J23/F23,"")) -> 0.87096774 | AB23: =IFERROR((J23-K23)/J23,"") -> 1 | AC23: =IFERROR(ROUNDUP(W23/I23,0),"") -> 41 | AD23: Tiget予約枚数 | AI23: 3
A24: vol.22 | B24: YAGATE vol.22 | C24: 45777 | D24: 水 | E24: 新宿ハイジアV-1 | F24: 40 | G24: 友田オレ／リンドバーグ／イクラボブチャンチャン／シャワーカーテニスト／清水駿平／ベルナルド／おミルク | H24: =IF(G24="","",LEN(G24)-LEN(SUBSTITUTE(G24,"／",""))+1) -> 7 | I24: 1500 | J24: 14 | L24: =IF(OR(I24="",J24=""),"",I24*J24) -> 21000 | R24: =IF(COUNT(L24:Q24)=0,"",SUM(L24:Q24)) -> 21000 | S24: =IFERROR(INDEX(会場マスタ!$C$2:$C$12,MATCH(E24,会場マスタ!$A$2:$A$12,0)),"") -> 45000 | T24: =IF(AI24="","",AI24*ガイド!$C$9) -> 12000 | U24: =ガイド!$C$10 -> 4000 | V24: =IF(L24="","",ROUND(L24*ガイド!$C$6,0)) -> 0 | W24: =IF(COUNT(S24:V24)=0,"",SUM(S24:V24)) -> 61000 | X24: =IF(AND(R24="",W24=""),"",SUM(R24)-SUM(W24)) -> -40000 | Y24: =IFERROR(X24/R24,"") -> -1.9047619 | Z24: =IFERROR(R24/J24,"") -> 1500 | AA24: =IF(OR(J24="",F24=""),"",IFERROR(J24/F24,"")) -> 0.35 | AB24: =IFERROR((J24-K24)/J24,"") -> 1 | AC24: =IFERROR(ROUNDUP(W24/I24,0),"") -> 41 | AD24: Tiget予約枚数 | AI24: 3
A25: vol.23 | B25: YAGATE vol.23 | C25: 45803 | D25: 月 | E25: 新宿ハイジアV-1 | F25: 45 | G25: 友田オレ／リンドバーグ／イクラボブチャンチャン／シャワーカーテニスト／ガングリオン／テツロー／ボブのコーラ | H25: =IF(G25="","",LEN(G25)-LEN(SUBSTITUTE(G25,"／",""))+1) -> 7 | I25: 1500 | J25: 27 | L25: =IF(OR(I25="",J25=""),"",I25*J25) -> 40500 | R25: =IF(COUNT(L25:Q25)=0,"",SUM(L25:Q25)) -> 40500 | S25: =IFERROR(INDEX(会場マスタ!$C$2:$C$12,MATCH(E25,会場マスタ!$A$2:$A$12,0)),"") -> 45000 | T25: =IF(AI25="","",AI25*ガイド!$C$9) -> 12000 | U25: =ガイド!$C$10 -> 4000 | V25: =IF(L25="","",ROUND(L25*ガイド!$C$6,0)) -> 0 | W25: =IF(COUNT(S25:V25)=0,"",SUM(S25:V25)) -> 61000 | X25: =IF(AND(R25="",W25=""),"",SUM(R25)-SUM(W25)) -> -20500 | Y25: =IFERROR(X25/R25,"") -> -0.50617284 | Z25: =IFERROR(R25/J25,"") -> 1500 | AA25: =IF(OR(J25="",F25=""),"",IFERROR(J25/F25,"")) -> 0.6 | AB25: =IFERROR((J25-K25)/J25,"") -> 1 | AC25: =IFERROR(ROUNDUP(W25/I25,0),"") -> 41 | AD25: Tiget予約枚数 | AI25: 3
A26: vol.24 | B26: YAGATE vol.24 | C26: 45838 | D26: 月 | E26: 新宿ハイジアV-1 | F26: 45 | G26: 友田オレ／リンドバーグ／イクラボブチャンチャン／シャワーカーテニスト／ダブルレンズ／スタミナパン | H26: =IF(G26="","",LEN(G26)-LEN(SUBSTITUTE(G26,"／",""))+1) -> 6 | I26: 1500 | J26: 18 | L26: =IF(OR(I26="",J26=""),"",I26*J26) -> 27000 | R26: =IF(COUNT(L26:Q26)=0,"",SUM(L26:Q26)) -> 27000 | S26: =IFERROR(INDEX(会場マスタ!$C$2:$C$12,MATCH(E26,会場マスタ!$A$2:$A$12,0)),"") -> 45000 | T26: =IF(AI26="","",AI26*ガイド!$C$9) -> 8000 | U26: =ガイド!$C$10 -> 4000 | V26: =IF(L26="","",ROUND(L26*ガイド!$C$6,0)) -> 0 | W26: =IF(COUNT(S26:V26)=0,"",SUM(S26:V26)) -> 57000 | X26: =IF(AND(R26="",W26=""),"",SUM(R26)-SUM(W26)) -> -30000 | Y26: =IFERROR(X26/R26,"") -> -1.1111111 | Z26: =IFERROR(R26/J26,"") -> 1500 | AA26: =IF(OR(J26="",F26=""),"",IFERROR(J26/F26,"")) -> 0.4 | AB26: =IFERROR((J26-K26)/J26,"") -> 1 | AC26: =IFERROR(ROUNDUP(W26/I26,0),"") -> 38 | AD26: Tiget予約枚数 | AI26: 2
A27: vol.25 | B27: YAGATE vol.25 | C27: 45862 | D27: 木 | E27: 新宿ハイジアV-1 | F27: 50 | G27: 友田オレ／リンドバーグ／イクラボブチャンチャン／シャワーカーテニスト／群青団地／照山おうちごはん | H27: =IF(G27="","",LEN(G27)-LEN(SUBSTITUTE(G27,"／",""))+1) -> 6 | I27: 1500 | J27: 27 | L27: =IF(OR(I27="",J27=""),"",I27*J27) -> 40500 | R27: =IF(COUNT(L27:Q27)=0,"",SUM(L27:Q27)) -> 40500 | S27: =IFERROR(INDEX(会場マスタ!$C$2:$C$12,MATCH(E27,会場マスタ!$A$2:$A$12,0)),"") -> 45000 | T27: =IF(AI27="","",AI27*ガイド!$C$9) -> 8000 | U27: =ガイド!$C$10 -> 4000 | V27: =IF(L27="","",ROUND(L27*ガイド!$C$6,0)) -> 0 | W27: =IF(COUNT(S27:V27)=0,"",SUM(S27:V27)) -> 57000 | X27: =IF(AND(R27="",W27=""),"",SUM(R27)-SUM(W27)) -> -16500 | Y27: =IFERROR(X27/R27,"") -> -0.40740741 | Z27: =IFERROR(R27/J27,"") -> 1500 | AA27: =IF(OR(J27="",F27=""),"",IFERROR(J27/F27,"")) -> 0.54 | AB27: =IFERROR((J27-K27)/J27,"") -> 1 | AC27: =IFERROR(ROUNDUP(W27/I27,0),"") -> 38 | AD27: Tiget予約枚数 | AI27: 2
A28: vol.26 | B28: YAGATE vol.26 | C28: 45894 | D28: 月 | E28: 下北沢シアターミネルヴァ | F28: 45 | G28: 友田オレ／リンドバーグ／イクラボブチャンチャン／シャワーカーテニスト／ド桜／あなたとネ | H28: =IF(G28="","",LEN(G28)-LEN(SUBSTITUTE(G28,"／",""))+1) -> 6 | I28: 1500 | J28: 34 | L28: 41500 | R28: =IF(COUNT(L28:Q28)=0,"",SUM(L28:Q28)) -> 41500 | S28: 30000 | T28: 12800 | U28: 3000 | V28: =IF(L28="","",ROUND(L28*ガイド!$C$6,0)) -> 0 | W28: =IF(COUNT(S28:V28)=0,"",SUM(S28:V28)) -> 45800 | X28: =IF(AND(R28="",W28=""),"",SUM(R28)-SUM(W28)) -> -4300 | Y28: =IFERROR(X28/R28,"") -> -0.10361446 | Z28: =IFERROR(R28/J28,"") -> 1220.5882 | AA28: =IF(OR(J28="",F28=""),"",IFERROR(J28/F28,"")) -> 0.75555556 | AB28: =IFERROR((J28-K28)/J28,"") -> 1 | AC28: =IFERROR(ROUNDUP(W28/I28,0),"") -> 31 | AD28: Tiget予約枚数 | AI28: 2
A29: vol.27 | B29: YAGATE vol.27 | C29: 45929 | D29: 月 | E29: 下北沢シアターミネルヴァ | F29: 45 | G29: 友田オレ／リンドバーグ／イクラボブチャンチャン／シャワーカーテニスト／大王／サツマカワRPG | H29: =IF(G29="","",LEN(G29)-LEN(SUBSTITUTE(G29,"／",""))+1) -> 6 | I29: 1500 | J29: 20 | L29: 24000 | R29: =IF(COUNT(L29:Q29)=0,"",SUM(L29:Q29)) -> 24000 | S29: 30000 | T29: 10600 | U29: 3000 | V29: =IF(L29="","",ROUND(L29*ガイド!$C$6,0)) -> 0 | W29: =IF(COUNT(S29:V29)=0,"",SUM(S29:V29)) -> 43600 | X29: =IF(AND(R29="",W29=""),"",SUM(R29)-SUM(W29)) -> -19600 | Y29: =IFERROR(X29/R29,"") -> -0.81666667 | Z29: =IFERROR(R29/J29,"") -> 1200 | AA29: =IF(OR(J29="",F29=""),"",IFERROR(J29/F29,"")) -> 0.44444444 | AB29: =IFERROR((J29-K29)/J29,"") -> 1 | AC29: =IFERROR(ROUNDUP(W29/I29,0),"") -> 30 | AD29: 日付はTiget表記2025/09/29(月)を採用（サイト表記は09/30） | AI29: 2
A30: vol.28 | B30: YAGATE vol.28 | C30: 45961 | D30: 金 | E30: 新宿ハイジアV-1 | F30: 50 | G30: 友田オレ／リンドバーグ／イクラボブチャンチャン／シャワーカーテニスト／軟水／カナメストーン | H30: =IF(G30="","",LEN(G30)-LEN(SUBSTITUTE(G30,"／",""))+1) -> 6 | I30: 1500 | J30: 35 | L30: =IF(OR(I30="",J30=""),"",I30*J30) -> 52500 | R30: =IF(COUNT(L30:Q30)=0,"",SUM(L30:Q30)) -> 52500 | S30: =IFERROR(INDEX(会場マスタ!$C$2:$C$12,MATCH(E30,会場マスタ!$A$2:$A$12,0)),"") -> 45000 | T30: =IF(AI30="","",AI30*ガイド!$C$9) -> 8000 | U30: =ガイド!$C$10 -> 4000 | V30: =IF(L30="","",ROUND(L30*ガイド!$C$6,0)) -> 0 | W30: =IF(COUNT(S30:V30)=0,"",SUM(S30:V30)) -> 57000 | X30: =IF(AND(R30="",W30=""),"",SUM(R30)-SUM(W30)) -> -4500 | Y30: =IFERROR(X30/R30,"") -> -0.085714286 | Z30: =IFERROR(R30/J30,"") -> 1500 | AA30: =IF(OR(J30="",F30=""),"",IFERROR(J30/F30,"")) -> 0.7 | AB30: =IFERROR((J30-K30)/J30,"") -> 1 | AC30: =IFERROR(ROUNDUP(W30/I30,0),"") -> 38 | AD30: Tiget予約枚数 | AI30: 2
A31: vol.29 | B31: YAGATE vol.29 | C31: 45982 | D31: 金 | E31: 新宿ハイジアV-1 | F31: 50 | G31: 友田オレ／リンドバーグ／イクラボブチャンチャン／シャワーカーテニスト／今夜も星が綺麗／ピュート | H31: =IF(G31="","",LEN(G31)-LEN(SUBSTITUTE(G31,"／",""))+1) -> 6 | I31: 1500 | J31: 33 | L31: =IF(OR(I31="",J31=""),"",I31*J31) -> 49500 | R31: =IF(COUNT(L31:Q31)=0,"",SUM(L31:Q31)) -> 49500 | S31: =IFERROR(INDEX(会場マスタ!$C$2:$C$12,MATCH(E31,会場マスタ!$A$2:$A$12,0)),"") -> 45000 | T31: =IF(AI31="","",AI31*ガイド!$C$9) -> 8000 | U31: =ガイド!$C$10 -> 4000 | V31: =IF(L31="","",ROUND(L31*ガイド!$C$6,0)) -> 0 | W31: =IF(COUNT(S31:V31)=0,"",SUM(S31:V31)) -> 57000 | X31: =IF(AND(R31="",W31=""),"",SUM(R31)-SUM(W31)) -> -7500 | Y31: =IFERROR(X31/R31,"") -> -0.15151515 | Z31: =IFERROR(R31/J31,"") -> 1500 | AA31: =IF(OR(J31="",F31=""),"",IFERROR(J31/F31,"")) -> 0.66 | AB31: =IFERROR((J31-K31)/J31,"") -> 1 | AC31: =IFERROR(ROUNDUP(W31/I31,0),"") -> 38 | AD31: 学割あり | AI31: 2
A32: vol.30 | B32: YAGATE vol.30 | C32: 46014 | D32: 火 | E32: 新宿ハイジアV-1 | F32: 45 | G32: 友田オレ／リンドバーグ／イクラボブチャンチャン／シャワーカーテニスト／金魚番長／無尽蔵 | H32: =IF(G32="","",LEN(G32)-LEN(SUBSTITUTE(G32,"／",""))+1) -> 6 | I32: 1500 | J32: 29 | L32: =IF(OR(I32="",J32=""),"",I32*J32) -> 43500 | R32: =IF(COUNT(L32:Q32)=0,"",SUM(L32:Q32)) -> 43500 | S32: =IFERROR(INDEX(会場マスタ!$C$2:$C$12,MATCH(E32,会場マスタ!$A$2:$A$12,0)),"") -> 45000 | T32: =IF(AI32="","",AI32*ガイド!$C$9) -> 8000 | U32: =ガイド!$C$10 -> 4000 | V32: =IF(L32="","",ROUND(L32*ガイド!$C$6,0)) -> 0 | W32: =IF(COUNT(S32:V32)=0,"",SUM(S32:V32)) -> 57000 | X32: =IF(AND(R32="",W32=""),"",SUM(R32)-SUM(W32)) -> -13500 | Y32: =IFERROR(X32/R32,"") -> -0.31034483 | Z32: =IFERROR(R32/J32,"") -> 1500 | AA32: =IF(OR(J32="",F32=""),"",IFERROR(J32/F32,"")) -> 0.64444444 | AB32: =IFERROR((J32-K32)/J32,"") -> 1 | AC32: =IFERROR(ROUNDUP(W32/I32,0),"") -> 38 | AD32: 学割あり | AI32: 2
A33: vol.31 | B33: YAGATE vol.31 | C33: 46048 | D33: 月 | E33: 新宿ハイジアV-1 | F33: 60 | G33: 友田オレ／リンドバーグ／イクラボブチャンチャン／シャワーカーテニスト／金魚番長／無尽蔵 | H33: =IF(G33="","",LEN(G33)-LEN(SUBSTITUTE(G33,"／",""))+1) -> 6 | I33: 1500 | J33: 44 | L33: =IF(OR(I33="",J33=""),"",I33*J33) -> 66000 | R33: =IF(COUNT(L33:Q33)=0,"",SUM(L33:Q33)) -> 66000 | S33: =IFERROR(INDEX(会場マスタ!$C$2:$C$12,MATCH(E33,会場マスタ!$A$2:$A$12,0)),"") -> 45000 | T33: =IF(AI33="","",AI33*ガイド!$C$9) -> 8000 | U33: =ガイド!$C$10 -> 4000 | V33: =IF(L33="","",ROUND(L33*ガイド!$C$6,0)) -> 0 | W33: =IF(COUNT(S33:V33)=0,"",SUM(S33:V33)) -> 57000 | X33: =IF(AND(R33="",W33=""),"",SUM(R33)-SUM(W33)) -> 9000 | Y33: =IFERROR(X33/R33,"") -> 0.13636364 | Z33: =IFERROR(R33/J33,"") -> 1500 | AA33: =IF(OR(J33="",F33=""),"",IFERROR(J33/F33,"")) -> 0.73333333 | AB33: =IFERROR((J33-K33)/J33,"") -> 1 | AC33: =IFERROR(ROUNDUP(W33/I33,0),"") -> 38 | AD33: Tiget予約枚数 | AI33: 2
A34: vol.32 | B34: YAGATE vol.32 | C34: 46073 | D34: 金 | E34: 新宿ハイジアV-1 | F34: 50 | G34: リンドバーグ／イクラボブチャンチャン／シャワーカーテニスト／兄弟／百恵 | H34: =IF(G34="","",LEN(G34)-LEN(SUBSTITUTE(G34,"／",""))+1) -> 5 | I34: 1500 | J34: 21 | L34: =IF(OR(I34="",J34=""),"",I34*J34) -> 31500 | R34: =IF(COUNT(L34:Q34)=0,"",SUM(L34:Q34)) -> 31500 | S34: =IFERROR(INDEX(会場マスタ!$C$2:$C$12,MATCH(E34,会場マスタ!$A$2:$A$12,0)),"") -> 45000 | T34: =IF(AI34="","",AI34*ガイド!$C$9) -> 8000 | U34: =ガイド!$C$10 -> 4000 | V34: =IF(L34="","",ROUND(L34*ガイド!$C$6,0)) -> 0 | W34: =IF(COUNT(S34:V34)=0,"",SUM(S34:V34)) -> 57000 | X34: =IF(AND(R34="",W34=""),"",SUM(R34)-SUM(W34)) -> -25500 | Y34: =IFERROR(X34/R34,"") -> -0.80952381 | Z34: =IFERROR(R34/J34,"") -> 1500 | AA34: =IF(OR(J34="",F34=""),"",IFERROR(J34/F34,"")) -> 0.42 | AB34: =IFERROR((J34-K34)/J34,"") -> 1 | AC34: =IFERROR(ROUNDUP(W34/I34,0),"") -> 38 | AD34: Tiget予約枚数 | AI34: 2
A35: vol.33 | B35: YAGATE vol.33 -SPECIAL- | C35: 46096 | D35: 日 | E35: 新宿ハイジアV-1 | G35: 友田オレ／リンドバーグ／イクラボブチャンチャン／シャワーカーテニスト／ハリセンボン | H35: =IF(G35="","",LEN(G35)-LEN(SUBSTITUTE(G35,"／",""))+1) -> 5 | I35: 2500 | J35: 74 | L35: =IF(OR(I35="",J35=""),"",I35*J35) -> 185000 | R35: =IF(COUNT(L35:Q35)=0,"",SUM(L35:Q35)) -> 185000 | S35: =IFERROR(INDEX(会場マスタ!$C$2:$C$12,MATCH(E35,会場マスタ!$A$2:$A$12,0)),"") -> 45000 | T35: =IF(AI35="","",AI35*ガイド!$C$9) -> 4000 | U35: =ガイド!$C$10 -> 4000 | V35: =IF(L35="","",ROUND(L35*ガイド!$C$6,0)) -> 0 | W35: =IF(COUNT(S35:V35)=0,"",SUM(S35:V35)) -> 53000 | X35: =IF(AND(R35="",W35=""),"",SUM(R35)-SUM(W35)) -> 132000 | Y35: =IFERROR(X35/R35,"") -> 0.71351351 | Z35: =IFERROR(R35/J35,"") -> 2500 | AA35: =IF(OR(J35="",F35=""),"",IFERROR(J35/F35,"")) | AB35: =IFERROR((J35-K35)/J35,"") -> 1 | AC35: =IFERROR(ROUNDUP(W35/I35,0),"") -> 22 | AD35: 単価2,500円は仮置き（一般185+247枚／桟敷39+43枚）。要確認 | AI35: 1
A36: vol.34 | B36: YAGATE vol.34 | C36: 46133 | D36: 火 | E36: 新宿ハイジアV-1 | F36: 65 | G36: 友田オレ／リンドバーグ／イクラボブチャンチャン／シャワーカーテニスト／ケビンス／お抹茶 | H36: =IF(G36="","",LEN(G36)-LEN(SUBSTITUTE(G36,"／",""))+1) -> 6 | I36: 1500 | J36: 64 | L36: =IF(OR(I36="",J36=""),"",I36*J36) -> 96000 | R36: =IF(COUNT(L36:Q36)=0,"",SUM(L36:Q36)) -> 96000 | S36: =IFERROR(INDEX(会場マスタ!$C$2:$C$12,MATCH(E36,会場マスタ!$A$2:$A$12,0)),"") -> 45000 | T36: =IF(AI36="","",AI36*ガイド!$C$9) -> 8000 | U36: =ガイド!$C$10 -> 4000 | V36: =IF(L36="","",ROUND(L36*ガイド!$C$6,0)) -> 0 | W36: =IF(COUNT(S36:V36)=0,"",SUM(S36:V36)) -> 57000 | X36: =IF(AND(R36="",W36=""),"",SUM(R36)-SUM(W36)) -> 39000 | Y36: =IFERROR(X36/R36,"") -> 0.40625 | Z36: =IFERROR(R36/J36,"") -> 1500 | AA36: =IF(OR(J36="",F36=""),"",IFERROR(J36/F36,"")) -> 0.98461538 | AB36: =IFERROR((J36-K36)/J36,"") -> 1 | AC36: =IFERROR(ROUNDUP(W36/I36,0),"") -> 38 | AD36: ほぼ完売 | AI36: 2
A37: vol.35 | B37: YAGATE vol.35 | C37: 46167 | D37: 月 | E37: 新宿ハイジアV-1 | F37: 65 | G37: 友田オレ／リンドバーグ舛谷／イクラボブチャンチャン／シャワーカーテニスト／深海魚／リバーサイドマエストロ／一向聴 | H37: =IF(G37="","",LEN(G37)-LEN(SUBSTITUTE(G37,"／",""))+1) -> 7 | I37: 1500 | J37: 28 | L37: =IF(OR(I37="",J37=""),"",I37*J37) -> 42000 | R37: =IF(COUNT(L37:Q37)=0,"",SUM(L37:Q37)) -> 42000 | S37: =IFERROR(INDEX(会場マスタ!$C$2:$C$12,MATCH(E37,会場マスタ!$A$2:$A$12,0)),"") -> 45000 | T37: =IF(AI37="","",AI37*ガイド!$C$9) -> 0 | U37: =ガイド!$C$10 -> 4000 | V37: =IF(L37="","",ROUND(L37*ガイド!$C$6,0)) -> 0 | W37: =IF(COUNT(S37:V37)=0,"",SUM(S37:V37)) -> 49000 | X37: =IF(AND(R37="",W37=""),"",SUM(R37)-SUM(W37)) -> -7000 | Y37: =IFERROR(X37/R37,"") -> -0.16666667 | Z37: =IFERROR(R37/J37,"") -> 1500 | AA37: =IF(OR(J37="",F37=""),"",IFERROR(J37/F37,"")) -> 0.43076923 | AB37: =IFERROR((J37-K37)/J37,"") -> 1 | AC37: =IFERROR(ROUNDUP(W37/I37,0),"") -> 33 | AD37: Tiget予約枚数 | AI37: 0
A38: vol.36 | B38: YAGATE vol.36 | C38: 46196 | D38: 火 | E38: 新宿ハイジアV-1 | F38: 65 | G38: 友田オレ／リンドバーグ／イクラボブチャンチャン／シャワーカーテニスト／深海魚／リバーサイドマエストロ／一向聴 | H38: =IF(G38="","",LEN(G38)-LEN(SUBSTITUTE(G38,"／",""))+1) -> 7 | I38: 1500 | J38: 19 | L38: =IF(OR(I38="",J38=""),"",I38*J38) -> 28500 | R38: =IF(COUNT(L38:Q38)=0,"",SUM(L38:Q38)) -> 28500 | S38: =IFERROR(INDEX(会場マスタ!$C$2:$C$12,MATCH(E38,会場マスタ!$A$2:$A$12,0)),"") -> 45000 | T38: =IF(AI38="","",AI38*ガイド!$C$9) -> 0 | U38: =ガイド!$C$10 -> 4000 | V38: =IF(L38="","",ROUND(L38*ガイド!$C$6,0)) -> 0 | W38: =IF(COUNT(S38:V38)=0,"",SUM(S38:V38)) -> 49000 | X38: =IF(AND(R38="",W38=""),"",SUM(R38)-SUM(W38)) -> -20500 | Y38: =IFERROR(X38/R38,"") -> -0.71929825 | Z38: =IFERROR(R38/J38,"") -> 1500 | AA38: =IF(OR(J38="",F38=""),"",IFERROR(J38/F38,"")) -> 0.29230769 | AB38: =IFERROR((J38-K38)/J38,"") -> 1 | AC38: =IFERROR(ROUNDUP(W38/I38,0),"") -> 33 | AD38: Tiget予約枚数 | AI38: 0
A39: vol.37 | B39: YAGATE vol.37 | C39: 46230 | D39: 月 | E39: 新宿ハイジアV-1 | F39: 65 | G39: 友田オレ／リンドバーグ／イクラボブチャンチャン／シャワーカーテニスト／深海魚／リバーサイドマエストロ／一向聴／チェット／無尽蔵 | H39: =IF(G39="","",LEN(G39)-LEN(SUBSTITUTE(G39,"／",""))+1) -> 9 | I39: 1500 | J39: 44 | L39: =IF(OR(I39="",J39=""),"",I39*J39) -> 66000 | R39: =IF(COUNT(L39:Q39)=0,"",SUM(L39:Q39)) -> 66000 | S39: =IFERROR(INDEX(会場マスタ!$C$2:$C$12,MATCH(E39,会場マスタ!$A$2:$A$12,0)),"") -> 45000 | T39: =IF(AI39="","",AI39*ガイド!$C$9) -> 4000 | U39: =ガイド!$C$10 -> 4000 | V39: =IF(L39="","",ROUND(L39*ガイド!$C$6,0)) -> 0 | W39: =IF(COUNT(S39:V39)=0,"",SUM(S39:V39)) -> 53000 | X39: =IF(AND(R39="",W39=""),"",SUM(R39)-SUM(W39)) -> 13000 | Y39: =IFERROR(X39/R39,"") -> 0.1969697 | Z39: =IFERROR(R39/J39,"") -> 1500 | AA39: =IF(OR(J39="",F39=""),"",IFERROR(J39/F39,"")) -> 0.67692308 | AB39: =IFERROR((J39-K39)/J39,"") -> 1 | AC39: =IFERROR(ROUNDUP(W39/I39,0),"") -> 36 | AD39: Tiget予約枚数 | AI39: 1
A40: vol.38 | B40: YAGATE vol.38 | C40: 46265 | D40: 月 | E40: 新宿ハイジアV-1 | G40: リンドバーグ／イクラボブチャンチャン／シャワーカーテニスト／深海魚／リバーサイドマエストロ／一向聴／チェット／群青団地 | H40: =IF(G40="","",LEN(G40)-LEN(SUBSTITUTE(G40,"／",""))+1) -> 8 | I40: 1500 | L40: =IF(OR(I40="",J40=""),"",I40*J40) | R40: =IF(COUNT(L40:Q40)=0,"",SUM(L40:Q40)) | V40: =IF(L40="","",ROUND(L40*ガイド!$C$6,0)) | W40: =IF(COUNT(S40:V40)=0,"",SUM(S40:V40)) | X40: =IF(AND(R40="",W40=""),"",SUM(R40)-SUM(W40)) | Y40: =IFERROR(X40/R40,"") | Z40: =IFERROR(R40/J40,"") | AA40: =IF(OR(J40="",F40=""),"",IFERROR(J40/F40,"")) | AB40: =IFERROR((J40-K40)/J40,"") | AC40: =IFERROR(ROUNDUP(W40/I40,0),"") | AD40: 友田オレ休演／販売中 | AI40: 1
...

Sheet 予約者ログ
A1: 公演回 | B1: 予約者ID（メール等） | C1: 氏名 | D1: 流入経路 | E1: 枚数 | F1: 新規/リピート
F2: =IF($B2="","",IF(COUNTIF($B$2:$B2,$B2)=1,"新規","リピート"))
F3: =IF($B3="","",IF(COUNTIF($B$2:$B3,$B3)=1,"新規","リピート"))
F4: =IF($B4="","",IF(COUNTIF($B$2:$B4,$B4)=1,"新規","リピート"))
F5: =IF($B5="","",IF(COUNTIF($B$2:$B5,$B5)=1,"新規","リピート"))
F6: =IF($B6="","",IF(COUNTIF($B$2:$B6,$B6)=1,"新規","リピート"))
F7: =IF($B7="","",IF(COUNTIF($B$2:$B7,$B7)=1,"新規","リピート"))
F8: =IF($B8="","",IF(COUNTIF($B$2:$B8,$B8)=1,"新規","リピート"))
F9: =IF($B9="","",IF(COUNTIF($B$2:$B9,$B9)=1,"新規","リピート"))
F10: =IF($B10="","",IF(COUNTIF($B$2:$B10,$B10)=1,"新規","リピート"))
F11: =IF($B11="","",IF(COUNTIF($B$2:$B11,$B11)=1,"新規","リピート"))
F12: =IF($B12="","",IF(COUNTIF($B$2:$B12,$B12)=1,"新規","リピート"))
F13: =IF($B13="","",IF(COUNTIF($B$2:$B13,$B13)=1,"新規","リピート"))
... F600: =IF($B600="","",IF(COUNTIF($B$2:$B600,$B600)=1,"新規","リピート"))
A602: ※ Tigetの予約者CSVをA〜E列に貼り付けてください。F列は自動判定です。
A603: ※ 予約者IDはメールアドレスなど、同一人物を一意に識別できる値を使ってください。

Sheet 流入元
A1: 回数 | B1: 総アクセス | C1: Twitter | D1: Google検索 | E1: Instagram | F1: お笑い情報サイト | G1: その他 | H1: 販売枚数 | I1: CVR | J1: 予測枚数 | K1: 予測との差 | L1: 販売日数 | M1: =IFERROR(SLOPE(H2:H37,B2:B37),"") -> 0.043858367 | N1: =IFERROR(INTERCEPT(H2:H37,B2:B37),"") -> 2.4868481
A2: vol.1 | B2: 326 | C2: 161 | D2: 10 | E2: 2 | F2: 12 | G2: =IF(B2="","",B2-SUM(C2:F2)) -> 141 | H2: =IFERROR(公演データ!$J$3,"") -> 16 | I2: =IFERROR(H2/B2,"") -> 0.049079755 | J2: =IFERROR(ROUND($M$1*B2+$N$1,1),"") -> 16.8 | K2: =IFERROR(H2-J2,"") -> -0.8
A3: vol.2 | B3: 418 | C3: 219 | D3: 10 | E3: 0 | F3: 9 | G3: =IF(B3="","",B3-SUM(C3:F3)) -> 180 | H3: =IFERROR(公演データ!$J$4,"") -> 13 | I3: =IFERROR(H3/B3,"") -> 0.031100478 | J3: =IFERROR(ROUND($M$1*B3+$N$1,1),"") -> 20.8 | K3: =IFERROR(H3-J3,"") -> -7.8
A4: vol.3 | B4: 606 | C4: 264 | D4: 0 | E4: 24 | F4: 82 | G4: =IF(B4="","",B4-SUM(C4:F4)) -> 236 | H4: =IFERROR(公演データ!$J$5,"") -> 30 | I4: =IFERROR(H4/B4,"") -> 0.04950495 | J4: =IFERROR(ROUND($M$1*B4+$N$1,1),"") -> 29.1 | K4: =IFERROR(H4-J4,"") -> 0.9
A5: vol.4 | B5: 510 | C5: 329 | D5: 43 | E5: 7 | F5: 23 | G5: =IF(B5="","",B5-SUM(C5:F5)) -> 108 | H5: =IFERROR(公演データ!$J$6,"") -> 16 | I5: =IFERROR(H5/B5,"") -> 0.031372549 | J5: =IFERROR(ROUND($M$1*B5+$N$1,1),"") -> 24.9 | K5: =IFERROR(H5-J5,"") -> -8.9
A6: vol.5 | B6: 850 | C6: 476 | D6: 102 | E6: 7 | F6: 48 | G6: =IF(B6="","",B6-SUM(C6:F6)) -> 217 | H6: =IFERROR(公演データ!$J$7,"") -> 25 | I6: =IFERROR(H6/B6,"") -> 0.029411765 | J6: =IFERROR(ROUND($M$1*B6+$N$1,1),"") -> 39.8 | K6: =IFERROR(H6-J6,"") -> -14.8
A7: vol.6 | B7: 405 | C7: 181 | D7: 49 | E7: 22 | F7: 21 | G7: =IF(B7="","",B7-SUM(C7:F7)) -> 132 | H7: =IFERROR(公演データ!$J$8,"") -> 19 | I7: =IFERROR(H7/B7,"") -> 0.04691358 | J7: =IFERROR(ROUND($M$1*B7+$N$1,1),"") -> 20.2 | K7: =IFERROR(H7-J7,"") -> -1.2
A8: vol.7 | B8: 347 | C8: 182 | D8: 50 | E8: 7 | F8: 15 | G8: =IF(B8="","",B8-SUM(C8:F8)) -> 93 | H8: =IFERROR(公演データ!$J$9,"") -> 14 | I8: =IFERROR(H8/B8,"") -> 0.040345821 | J8: =IFERROR(ROUND($M$1*B8+$N$1,1),"") -> 17.7 | K8: =IFERROR(H8-J8,"") -> -3.7
A9: vol.8 | B9: 965 | C9: 462 | D9: 107 | E9: 13 | F9: 153 | G9: =IF(B9="","",B9-SUM(C9:F9)) -> 230 | H9: =IFERROR(公演データ!$J$10,"") -> 60 | I9: =IFERROR(H9/B9,"") -> 0.062176166 | J9: =IFERROR(ROUND($M$1*B9+$N$1,1),"") -> 44.8 | K9: =IFERROR(H9-J9,"") -> 15.2
A10: vol.9 | B10: 817 | C10: 503 | D10: 102 | E10: 36 | F10: 52 | G10: =IF(B10="","",B10-SUM(C10:F10)) -> 124 | H10: =IFERROR(公演データ!$J$11,"") -> 42 | I10: =IFERROR(H10/B10,"") -> 0.051407589 | J10: =IFERROR(ROUND($M$1*B10+$N$1,1),"") -> 38.3 | K10: =IFERROR(H10-J10,"") -> 3.7
A11: vol.10 | B11: 452 | C11: 270 | D11: 43 | E11: 19 | F11: 10 | G11: =IF(B11="","",B11-SUM(C11:F11)) -> 110 | H11: =IFERROR(公演データ!$J$12,"") -> 32 | I11: =IFERROR(H11/B11,"") -> 0.07079646 | J11: =IFERROR(ROUND($M$1*B11+$N$1,1),"") -> 22.3 | K11: =IFERROR(H11-J11,"") -> 9.7
A12: vol.11 | B12: 744 | C12: 368 | D12: 106 | E12: 11 | F12: 74 | G12: =IF(B12="","",B12-SUM(C12:F12)) -> 185 | H12: =IFERROR(公演データ!$J$13,"") -> 33 | I12: =IFERROR(H12/B12,"") -> 0.044354839 | J12: =IFERROR(ROUND($M$1*B12+$N$1,1),"") -> 35.1 | K12: =IFERROR(H12-J12,"") -> -2.1
A13: vol.12 | B13: 355 | C13: 176 | D13: 63 | E13: 3 | F13: 15 | G13: =IF(B13="","",B13-SUM(C13:F13)) -> 98 | H13: =IFERROR(公演データ!$J$14,"") -> 14 | I13: =IFERROR(H13/B13,"") -> 0.03943662 | J13: =IFERROR(ROUND($M$1*B13+$N$1,1),"") -> 18.1 | K13: =IFERROR(H13-J13,"") -> -4.1
A14: vol.13 | B14: 427 | C14: 283 | D14: 63 | E14: 0 | F14: 3 | G14: =IF(B14="","",B14-SUM(C14:F14)) -> 78 | H14: =IFERROR(公演データ!$J$15,"") -> 22 | I14: =IFERROR(H14/B14,"") -> 0.051522248 | J14: =IFERROR(ROUND($M$1*B14+$N$1,1),"") -> 21.2 | K14: =IFERROR(H14-J14,"") -> 0.8
A15: vol.14 | B15: 419 | C15: 222 | D15: 65 | E15: 16 | F15: 21 | G15: =IF(B15="","",B15-SUM(C15:F15)) -> 95 | H15: =IFERROR(公演データ!$J$16,"") -> 16 | I15: =IFERROR(H15/B15,"") -> 0.038186158 | J15: =IFERROR(ROUND($M$1*B15+$N$1,1),"") -> 20.9 | K15: =IFERROR(H15-J15,"") -> -4.9
A16: vol.15 | B16: 598 | C16: 337 | D16: 79 | E16: 8 | F16: 16 | G16: =IF(B16="","",B16-SUM(C16:F16)) -> 158 | H16: =IFERROR(公演データ!$J$17,"") -> 38 | I16: =IFERROR(H16/B16,"") -> 0.063545151 | J16: =IFERROR(ROUND($M$1*B16+$N$1,1),"") -> 28.7 | K16: =IFERROR(H16-J16,"") -> 9.3
A17: vol.16 | B17: 270 | C17: 150 | D17: 45 | E17: 8 | F17: 7 | G17: =IF(B17="","",B17-SUM(C17:F17)) -> 60 | H17: =IFERROR(公演データ!$J$18,"") -> 13 | I17: =IFERROR(H17/B17,"") -> 0.048148148 | J17: =IFERROR(ROUND($M$1*B17+$N$1,1),"") -> 14.3 | K17: =IFERROR(H17-J17,"") -> -1.3
A18: vol.17 | B18: 424 | C18: 169 | D18: 93 | E18: 2 | F18: 16 | G18: =IF(B18="","",B18-SUM(C18:F18)) -> 144 | H18: =IFERROR(公演データ!$J$19,"") -> 32 | I18: =IFERROR(H18/B18,"") -> 0.075471698 | J18: =IFERROR(ROUND($M$1*B18+$N$1,1),"") -> 21.1 | K18: =IFERROR(H18-J18,"") -> 10.9
A19: vol.18 | B19: 161 | C19: 92 | D19: 19 | E19: 0 | F19: 5 | G19: =IF(B19="","",B19-SUM(C19:F19)) -> 45 | H19: =IFERROR(公演データ!$J$20,"") -> 11 | I19: =IFERROR(H19/B19,"") -> 0.068322981 | J19: =IFERROR(ROUND($M$1*B19+$N$1,1),"") -> 9.5 | K19: =IFERROR(H19-J19,"") -> 1.5
A20: vol.19 | B20: 317 | C20: 166 | D20: 40 | E20: 3 | F20: 15 | G20: =IF(B20="","",B20-SUM(C20:F20)) -> 93 | H20: =IFERROR(公演データ!$J$21,"") -> 21 | I20: =IFERROR(H20/B20,"") -> 0.066246057 | J20: =IFERROR(ROUND($M$1*B20+$N$1,1),"") -> 16.4 | K20: =IFERROR(H20-J20,"") -> 4.6
A21: vol.20 | B21: 333 | C21: 188 | D21: 48 | E21: 3 | F21: 7 | G21: =IF(B21="","",B21-SUM(C21:F21)) -> 87 | H21: =IFERROR(公演データ!$J$22,"") -> 19 | I21: =IFERROR(H21/B21,"") -> 0.057057057 | J21: =IFERROR(ROUND($M$1*B21+$N$1,1),"") -> 17.1 | K21: =IFERROR(H21-J21,"") -> 1.9
A22: vol.21 | B22: 1009 | C22: 466 | D22: 147 | E22: 75 | F22: 68 | G22: =IF(B22="","",B22-SUM(C22:F22)) -> 253 | H22: =IFERROR(公演データ!$J$23,"") -> 54 | I22: =IFERROR(H22/B22,"") -> 0.053518335 | J22: =IFERROR(ROUND($M$1*B22+$N$1,1),"") -> 46.7 | K22: =IFERROR(H22-J22,"") -> 7.3
A23: vol.22 | B23: 299 | C23: 108 | D23: 42 | E23: 33 | F23: 49 | G23: =IF(B23="","",B23-SUM(C23:F23)) -> 67 | H23: =IFERROR(公演データ!$J$24,"") -> 14 | I23: =IFERROR(H23/B23,"") -> 0.046822742 | J23: =IFERROR(ROUND($M$1*B23+$N$1,1),"") -> 15.6 | K23: =IFERROR(H23-J23,"") -> -1.6
A24: vol.23 | B24: 875 | C24: 326 | D24: 109 | E24: 130 | F24: 106 | G24: =IF(B24="","",B24-SUM(C24:F24)) -> 204 | H24: =IFERROR(公演データ!$J$25,"") -> 27 | I24: =IFERROR(H24/B24,"") -> 0.030857143 | J24: =IFERROR(ROUND($M$1*B24+$N$1,1),"") -> 40.9 | K24: =IFERROR(H24-J24,"") -> -13.9
A25: vol.24 | B25: 383 | C25: 202 | D25: 60 | E25: 6 | F25: 40 | G25: =IF(B25="","",B25-SUM(C25:F25)) -> 75 | H25: =IFERROR(公演データ!$J$26,"") -> 18 | I25: =IFERROR(H25/B25,"") -> 0.046997389 | J25: =IFERROR(ROUND($M$1*B25+$N$1,1),"") -> 19.3 | K25: =IFERROR(H25-J25,"") -> -1.3
A26: vol.25 | B26: 400 | C26: 170 | D26: 65 | E26: 48 | F26: 15 | G26: =IF(B26="","",B26-SUM(C26:F26)) -> 102 | H26: =IFERROR(公演データ!$J$27,"") -> 27 | I26: =IFERROR(H26/B26,"") -> 0.0675 | J26: =IFERROR(ROUND($M$1*B26+$N$1,1),"") -> 20 | K26: =IFERROR(H26-J26,"") -> 7
A27: vol.26 | B27: 656 | C27: 248 | D27: 83 | E27: 54 | F27: 44 | G27: =IF(B27="","",B27-SUM(C27:F27)) -> 227 | H27: =IFERROR(公演データ!$J$28,"") -> 34 | I27: =IFERROR(H27/B27,"") -> 0.051829268 | J27: =IFERROR(ROUND($M$1*B27+$N$1,1),"") -> 31.3 | K27: =IFERROR(H27-J27,"") -> 2.7
A28: vol.27 | B28: 612 | C28: 189 | D28: 119 | E28: 81 | F28: 39 | G28: =IF(B28="","",B28-SUM(C28:F28)) -> 184 | H28: =IFERROR(公演データ!$J$29,"") -> 20 | I28: =IFERROR(H28/B28,"") -> 0.032679739 | J28: =IFERROR(ROUND($M$1*B28+$N$1,1),"") -> 29.3 | K28: =IFERROR(H28-J28,"") -> -9.3
A29: vol.28 | B29: 804 | C29: 250 | D29: 175 | E29: 44 | F29: 12 | G29: =IF(B29="","",B29-SUM(C29:F29)) -> 323 | H29: =IFERROR(公演データ!$J$30,"") -> 35 | I29: =IFERROR(H29/B29,"") -> 0.043532338 | J29: =IFERROR(ROUND($M$1*B29+$N$1,1),"") -> 37.7 | K29: =IFERROR(H29-J29,"") -> -2.7
A30: vol.29 | B30: 591 | C30: 342 | D30: 67 | E30: 17 | F30: 39 | G30: =IF(B30="","",B30-SUM(C30:F30)) -> 126 | H30: =IFERROR(公演データ!$J$31,"") -> 33 | I30: =IFERROR(H30/B30,"") -> 0.055837563 | J30: =IFERROR(ROUND($M$1*B30+$N$1,1),"") -> 28.4 | K30: =IFERROR(H30-J30,"") -> 4.6
A31: vol.30 | B31: 471 | C31: 193 | D31: 81 | E31: 12 | F31: 36 | G31: =IF(B31="","",B31-SUM(C31:F31)) -> 149 | H31: =IFERROR(公演データ!$J$32,"") -> 29 | I31: =IFERROR(H31/B31,"") -> 0.061571125 | J31: =IFERROR(ROUND($M$1*B31+$N$1,1),"") -> 23.1 | K31: =IFERROR(H31-J31,"") -> 5.9
A32: vol.31 | B32: 1002 | C32: 375 | D32: 286 | E32: 22 | F32: 65 | G32: =IF(B32="","",B32-SUM(C32:F32)) -> 254 | H32: =IFERROR(公演データ!$J$33,"") -> 44 | I32: =IFERROR(H32/B32,"") -> 0.043912176 | J32: =IFERROR(ROUND($M$1*B32+$N$1,1),"") -> 46.4 | K32: =IFERROR(H32-J32,"") -> -2.4
A33: vol.32 | B33: 499 | C33: 145 | D33: 110 | E33: 21 | F33: 26 | G33: =IF(B33="","",B33-SUM(C33:F33)) -> 197 | H33: =IFERROR(公演データ!$J$34,"") -> 21 | I33: =IFERROR(H33/B33,"") -> 0.042084168 | J33: =IFERROR(ROUND($M$1*B33+$N$1,1),"") -> 24.4 | K33: =IFERROR(H33-J33,"") -> -3.4
A34: vol.34 | B34: 1399 | C34: 738 | D34: 222 | E34: 12 | F34: 42 | G34: =IF(B34="","",B34-SUM(C34:F34)) -> 385 | H34: =IFERROR(公演データ!$J$36,"") -> 64 | I34: =IFERROR(H34/B34,"") -> 0.045746962 | J34: =IFERROR(ROUND($M$1*B34+$N$1,1),"") -> 63.8 | K34: =IFERROR(H34-J34,"") -> 0.2 | L34: 23 | M34: 228
A35: vol.35 | B35: 625 | C35: 288 | D35: 97 | E35: 92 | F35: 6 | G35: =IF(B35="","",B35-SUM(C35:F35)) -> 142 | H35: =IFERROR(公演データ!$J$37,"") -> 28 | I35: =IFERROR(H35/B35,"") -> 0.0448 | J35: =IFERROR(ROUND($M$1*B35+$N$1,1),"") -> 29.9 | K35: =IFERROR(H35-J35,"") -> -1.9 | L35: 17 | M35: 32
A36: vol.36 | B36: 426 | C36: 125 | D36: 116 | E36: 47 | F36: 33 | G36: =IF(B36="","",B36-SUM(C36:F36)) -> 105 | H36: =IFERROR(公演データ!$J$38,"") -> 19 | I36: =IFERROR(H36/B36,"") -> 0.044600939 | J36: =IFERROR(ROUND($M$1*B36+$N$1,1),"") -> 21.2 | K36: =IFERROR(H36-J36,"") -> -2.2 | L36: 29 | M36: 32
A37: vol.37 | B37: 896 | C37: 292 | D37: 211 | E37: 111 | F37: 25 | G37: =IF(B37="","",B37-SUM(C37:F37)) -> 257 | H37: =IFERROR(公演データ!$J$39,"") -> 44 | I37: =IFERROR(H37/B37,"") -> 0.049107143 | J37: =IFERROR(ROUND($M$1*B37+$N$1,1),"") -> 41.8 | K37: =IFERROR(H37-J37,"") -> 2.2 | L37: 27 | M37: 115
A39: ※ 総アクセス・チャネル別はTigetの流入元画面より転記。vol.33は未取得。
A40: ※ 予測枚数＝全公演の回帰式（枚数＝傾き×アクセス＋切片）。M1/N1セルに係数を自動計算。
A41: ※ 販売日数・公開日ピークは日別グラフからの読み取り値（vol.34〜37のみ）。
